# import asyncio
# import logging
#
# import pytest
# from pydantic import ValidationError
# from socketio import AsyncClient
#
# from dslmodel.mq7.happy_client import UserSignedUpData, UserUpdatedData, SendNotificationData, UserDeletedData
#
#
# @pytest.fixture
# async def client():
#     from dslmodel.mq7.happy_client import sio, connect
#     await connect()
#     yield sio
#
#
# @pytest.mark.asyncio
# async def test_connect_to_server(client, caplog):
#     caplog.set_level(logging.INFO)
#     assert 'Successfully connected to the server.' in caplog.text
#
#
# @pytest.mark.asyncio
# async def test_user_signed_up_event(client, caplog):
#     caplog.set_level(logging.INFO)
#     try:
#         data = UserSignedUpData(fullName="Alice", email="alice@example.com", age=30).dict()
#         await client.emit('userSignedUp', data)
#         await asyncio.sleep(0.1)
#         assert 'Emitted userSignedUp event.' in caplog.text
#     except ValidationError:
#         pytest.fail("Validation error in userSignedUp event")
#
#
# @pytest.mark.asyncio
# async def test_user_updated_event(client, caplog):
#     caplog.set_level(logging.INFO)
#     try:
#         data = UserUpdatedData(userId="123", fullName="Alice", email="alice_updated@example.com", age=31).dict()
#         await client.emit('userUpdated', data)
#         await asyncio.sleep(0.1)
#         assert 'Emitted userUpdated event.' in caplog.text
#     except ValidationError:
#         pytest.fail("Validation error in userUpdated event")
#
#
# @pytest.mark.asyncio
# async def test_send_notification_event(client, caplog):
#     caplog.set_level(logging.INFO)
#     try:
#         data = SendNotificationData(userId="123", message="Welcome to the system!", priority="high").dict()
#         await client.emit('sendNotification', data)
#         await asyncio.sleep(0.1)
#         assert 'Emitted sendNotification event.' in caplog.text
#     except ValidationError:
#         pytest.fail("Validation error in sendNotification event")
#
#
# @pytest.mark.asyncio
# async def test_receive_user_deleted_event(client, caplog):
#     caplog.set_level(logging.INFO)
#
#     @client.event
#     async def userDeleted(data):
#         try:
#             validated_data = UserDeletedData(**data)
#             assert validated_data.userId == "123"
#             logging.info("Received userDeleted event.")
#         except ValidationError:
#             pytest.fail("Validation error in userDeleted event")
#
#     await asyncio.sleep(0.1)
#     assert 'Received userDeleted event.' in caplog.text
#
#
# @pytest.mark.asyncio
# async def test_handle_connect_error():
#     client = AsyncClient()
#
#     with pytest.raises(Exception):
#         await client.connect('http://localhost:9999')  # Incorrect address for error handling
#
#     await asyncio.sleep(0.1)
#     await client.disconnect()
#
#
# @pytest.mark.asyncio
# async def test_handle_disconnect_event(client, caplog):
#     caplog.set_level(logging.INFO)
#
#     @client.event
#     async def disconnect():
#         logging.info("Disconnected from server.")
#
#     await client.disconnect()
#     await asyncio.sleep(0.1)
#     assert 'Disconnected from server.' in caplog.text
